[32m2024-08-19 23:51:17 +0000[0m - dagster - [34mDEBUG[0m - __ASSET_JOB - 1dbbed3c-92f4-4d82-8f64-c43dd3f66c77 - 285121 - LOGS_CAPTURED - Started capturing logs in process (pid: 285121).
[32m2024-08-19 23:51:17 +0000[0m - dagster - [34mDEBUG[0m - __ASSET_JOB - 1dbbed3c-92f4-4d82-8f64-c43dd3f66c77 - 285121 - db_crypto_transfer_transactions - STEP_START - Started execution of step "db_crypto_transfer_transactions".
[32m2024-08-19 23:51:17 +0000[0m - dagster - [34mERROR[0m - [31m__ASSET_JOB - 1dbbed3c-92f4-4d82-8f64-c43dd3f66c77 - 285121 - db_crypto_transfer_transactions - STEP_FAILURE - Execution of step "db_crypto_transfer_transactions" failed.

dagster._core.errors.DagsterExecutionStepExecutionError: Error occurred while executing op "db_crypto_transfer_transactions"::

json.decoder.JSONDecodeError: Expecting value: line 1 column 1 (char 0)

Stack Trace:
  File "/workspace/.pyenv_mirror/poetry/virtualenvs/pipeline-z_B504z3-py3.12/lib/python3.12/site-packages/dagster/_core/execution/plan/utils.py", line 54, in op_execution_error_boundary
    yield
  File "/workspace/.pyenv_mirror/poetry/virtualenvs/pipeline-z_B504z3-py3.12/lib/python3.12/site-packages/dagster/_utils/__init__.py", line 474, in iterate_with_context
    next_output = next(iterator)
                  ^^^^^^^^^^^^^^
  File "/workspace/.pyenv_mirror/poetry/virtualenvs/pipeline-z_B504z3-py3.12/lib/python3.12/site-packages/dagster/_core/execution/plan/compute_generator.py", line 141, in _coerce_op_compute_fn_to_iterator
    result = invoke_compute_fn(
             ^^^^^^^^^^^^^^^^^^
  File "/workspace/.pyenv_mirror/poetry/virtualenvs/pipeline-z_B504z3-py3.12/lib/python3.12/site-packages/dagster/_core/execution/plan/compute_generator.py", line 129, in invoke_compute_fn
    return fn(context, **args_to_pass) if context_arg_provided else fn(**args_to_pass)
                                                                    ^^^^^^^^^^^^^^^^^^
  File "/workspace/pranatics/sources/pipeline/hedera_pipeline/hedera_pipeline/assets.py", line 61, in db_crypto_transfer_transactions
    transactions = json.loads(TRANSACTIONS_INITIAL_STORAGE_FILE)
                   ^^^^^^^^^^^^^^^^^^^^^^^^^^^^^^^^^^^^^^^^^^^^^
  File "/home/gitpod/.pyenv/versions/3.12.4/lib/python3.12/json/__init__.py", line 346, in loads
    return _default_decoder.decode(s)
           ^^^^^^^^^^^^^^^^^^^^^^^^^^
  File "/home/gitpod/.pyenv/versions/3.12.4/lib/python3.12/json/decoder.py", line 337, in decode
    obj, end = self.raw_decode(s, idx=_w(s, 0).end())
               ^^^^^^^^^^^^^^^^^^^^^^^^^^^^^^^^^^^^^^
  File "/home/gitpod/.pyenv/versions/3.12.4/lib/python3.12/json/decoder.py", line 355, in raw_decode
    raise JSONDecodeError("Expecting value", s, err.value) from None

The above exception occurred during handling of the following exception:
StopIteration: 0

Stack Trace:
  File "/home/gitpod/.pyenv/versions/3.12.4/lib/python3.12/json/decoder.py", line 353, in raw_decode
    obj, end = self.scan_once(s, idx)
               ^^^^^^^^^^^^^^^^^^^^^^
[0m
