[32m2024-08-20 00:59:12 +0000[0m - dagster - [34mDEBUG[0m - __ASSET_JOB - a0ecd415-bc78-44a2-960f-a586c8ed2130 - 464934 - LOGS_CAPTURED - Started capturing logs in process (pid: 464934).
[32m2024-08-20 00:59:12 +0000[0m - dagster - [34mDEBUG[0m - __ASSET_JOB - a0ecd415-bc78-44a2-960f-a586c8ed2130 - 464934 - predict_data - STEP_START - Started execution of step "predict_data".
00:59:12 - cmdstanpy - INFO - Chain [1] start processing
00:59:12 - cmdstanpy - INFO - Chain [1] done processing
[32m2024-08-20 00:59:13 +0000[0m - dagster - [34mERROR[0m - [31m__ASSET_JOB - a0ecd415-bc78-44a2-960f-a586c8ed2130 - 464934 - predict_data - STEP_FAILURE - Execution of step "predict_data" failed.

dagster._core.errors.DagsterExecutionStepExecutionError: Error occurred while executing op "predict_data"::

FileNotFoundError: [Errno 2] No such file or directory: 'data/plot/prediction_plot.png'

Stack Trace:
  File "/workspace/.pyenv_mirror/poetry/virtualenvs/pipeline-z_B504z3-py3.12/lib/python3.12/site-packages/dagster/_core/execution/plan/utils.py", line 54, in op_execution_error_boundary
    yield
  File "/workspace/.pyenv_mirror/poetry/virtualenvs/pipeline-z_B504z3-py3.12/lib/python3.12/site-packages/dagster/_utils/__init__.py", line 474, in iterate_with_context
    next_output = next(iterator)
                  ^^^^^^^^^^^^^^
  File "/workspace/.pyenv_mirror/poetry/virtualenvs/pipeline-z_B504z3-py3.12/lib/python3.12/site-packages/dagster/_core/execution/plan/compute_generator.py", line 141, in _coerce_op_compute_fn_to_iterator
    result = invoke_compute_fn(
             ^^^^^^^^^^^^^^^^^^
  File "/workspace/.pyenv_mirror/poetry/virtualenvs/pipeline-z_B504z3-py3.12/lib/python3.12/site-packages/dagster/_core/execution/plan/compute_generator.py", line 129, in invoke_compute_fn
    return fn(context, **args_to_pass) if context_arg_provided else fn(**args_to_pass)
                                                                    ^^^^^^^^^^^^^^^^^^
  File "/workspace/pranatics/sources/pipeline/hedera_pipeline/hedera_pipeline/assets.py", line 130, in predict_data
    pio.write_image(fig, CRYPTO_TRANSFER_PREDICTION_PLOT_FILE)
  File "/workspace/.pyenv_mirror/poetry/virtualenvs/pipeline-z_B504z3-py3.12/lib/python3.12/site-packages/plotly/io/_kaleido.py", line 296, in write_image
    path.write_bytes(img_data)
  File "/home/gitpod/.pyenv/versions/3.12.4/lib/python3.12/pathlib.py", line 1036, in write_bytes
    with self.open(mode='wb') as f:
         ^^^^^^^^^^^^^^^^^^^^
  File "/home/gitpod/.pyenv/versions/3.12.4/lib/python3.12/pathlib.py", line 1013, in open
    return io.open(self, mode, buffering, encoding, errors, newline)
           ^^^^^^^^^^^^^^^^^^^^^^^^^^^^^^^^^^^^^^^^^^^^^^^^^^^^^^^^^
[0m
